Workbook

Sheet Quy tac
A1: Quy tắc và tham số của mô hình
A2: Ô chữ xanh dương là tham số đầu vào: đổi số ở đây thì các cột tính toán trong sheet 'Nhat ky' tự tính lại.
A4: Tham số | B4: Giá trị | C4: Ý nghĩa
A5: Cơ số khả năng ghi nhớ | B5: 0.9 | C5: R = cơ số ^ (t / S): tại t = S, học viên còn nhớ 90%
A6: Ngưỡng độ yếu vào nhóm Yếu | B6: 0.5 | C6: Độ yếu ≥ 50%
A7: Số lần làm gần nhất dùng tính độ yếu | B7: 5 | C7: Độ yếu = (số sai + 1) / (số lần + 2) trên 5 lần gần nhất
A8: Thời gian nghỉ tối thiểu (giờ) | B8: 20 | C8: Câu làm chưa đủ 20 giờ thì không được chọn
A9: Số câu mỗi phiên | B9: 10
A10: Số câu mới tối thiểu mỗi phiên | B10: 3 | C10: Khi bể còn câu chưa làm
A11: Suất nhóm Yếu (phiên Cân bằng) | B11: 4 | C11: Trên 7 suất ôn tập
A12: Suất nhóm Sắp quên (phiên Cân bằng) | B12: 3 | C12: Trên 7 suất ôn tập
A15: Thang độ bền S (ngày)
A16: Bậc | B16: S (ngày) | C16: Diễn giải
A17: 1 | B17: 1 | C17: Lần đầu sai, hoặc vừa làm sai
A18: 2 | B18: 3 | C18: Lần đầu đúng
A19: 3 | B19: 7
A20: 4 | B20: 14
A21: 5 | B21: 30
A22: 6 | B22: 60 | C22: Bậc cao nhất
A24: Quy tắc đổi bậc
A25: • Lần làm đầu tiên: đúng → bậc 2 (3 ngày); sai → bậc 1 (1 ngày).
A26: • Làm sai: về bậc 1 (1 ngày), bất kể đang ở bậc nào.
A27: • Làm đúng khi đã đến hạn (t ≥ S): lên 1 bậc.
A28: • Làm đúng khi chưa đến hạn (t < S): giữ nguyên bậc. Nhớ lại khi chưa quên không làm trí nhớ bền thêm.
A29: • Nhóm Sắp quên: câu đã đến hạn (t ≥ S, tức R ≤ 90%), xếp R thấp lên trước.
A30: • Nhóm Yếu: độ yếu ≥ 50%, xếp độ yếu cao lên trước.
A31: • Một câu có thể thuộc cả hai nhóm; được chọn ở nhóm nào thì chỉ tính một lần.
A32: • Kết quả Đúng/Sai trong sheet 'Nhat ky' do một học viên giả lập sinh ra; mọi cột còn lại tính bằng công thức.

Sheet Nhat ky
A1: Phiên | B1: Ngày | C1: STT | D1: Mã câu | E1: Nhóm chọn | F1: Lịch sử 5 lần trước (cũ→mới) | G1: Độ yếu trước | H1: S trước (ngày) | I1: t: ngày từ lần làm cuối | J1: R trước | K1: Đã đến hạn? | L1: Kết quả | M1: Lịch sử sau | N1: Độ yếu sau | O1: S sau (ngày) | P1: Hạn ôn kế tiếp (ngày) | Q1: Quy tắc áp dụng
A2: 1 | B2: 1 | C2: 1 | D2: Q01 | E2: Mới | F2: — | G2: =IF(F2="—","—",(LEN(F2)-LEN(SUBSTITUTE(F2,"S",""))+1)/(LEN(F2)+2)) -> — | H2: — | I2: — | J2: =IF(H2="—","—",'Quy tac'!$B$5^(I2/H2)) -> — | K2: =IF(H2="—","Câu mới",IF(I2>=H2,"Có","Chưa")) -> Câu mới | L2: Đúng | M2: =RIGHT(IF(F2="—","",F2)&IF(L2="Đúng","Đ","S"),'Quy tac'!$B$7) -> Đ | N2: =(LEN(M2)-LEN(SUBSTITUTE(M2,"S",""))+1)/(LEN(M2)+2) -> 0.33333333 | O2: =IF(H2="—",IF(L2="Đúng",INDEX('Quy tac'!$B$17:$B$22,2),INDEX('Quy tac'!$B$17:$B$22,1)),IF(L2="Sai",INDEX('Quy tac'!$B$17:$B$22,1),IF(I2>=H2,INDEX('Quy tac'!$B$17:$B$22,MIN(MATCH(H2,'Quy tac'!$B$17:$B$22,0)+1,6)),H2))) -> 3 | P2: =B2+O2 -> 4 | Q2: =IF(H2="—",IF(L2="Đúng","Lần đầu đúng → 3 ngày","Lần đầu sai → 1 ngày"),IF(L2="Sai","Sai → về 1 ngày",IF(I2>=H2,"Đúng, đến hạn → lên 1 bậc","Đúng nhưng ôn sớm → giữ bậc"))) -> Lần đầu đúng → 3 ngày
A3: 1 | B3: 1 | C3: 2 | D3: Q02 | E3: Mới | F3: — | G3: =IF(F3="—","—",(LEN(F3)-LEN(SUBSTITUTE(F3,"S",""))+1)/(LEN(F3)+2)) -> — | H3: — | I3: — | J3: =IF(H3="—","—",'Quy tac'!$B$5^(I3/H3)) -> — | K3: =IF(H3="—","Câu mới",IF(I3>=H3,"Có","Chưa")) -> Câu mới | L3: Đúng | M3: =RIGHT(IF(F3="—","",F3)&IF(L3="Đúng","Đ","S"),'Quy tac'!$B$7) -> Đ | N3: =(LEN(M3)-LEN(SUBSTITUTE(M3,"S",""))+1)/(LEN(M3)+2) -> 0.33333333 | O3: =IF(H3="—",IF(L3="Đúng",INDEX('Quy tac'!$B$17:$B$22,2),INDEX('Quy tac'!$B$17:$B$22,1)),IF(L3="Sai",INDEX('Quy tac'!$B$17:$B$22,1),IF(I3>=H3,INDEX('Quy tac'!$B$17:$B$22,MIN(MATCH(H3,'Quy tac'!$B$17:$B$22,0)+1,6)),H3))) -> 3 | P3: =B3+O3 -> 4 | Q3: =IF(H3="—",IF(L3="Đúng","Lần đầu đúng → 3 ngày","Lần đầu sai → 1 ngày"),IF(L3="Sai","Sai → về 1 ngày",IF(I3>=H3,"Đúng, đến hạn → lên 1 bậc","Đúng nhưng ôn sớm → giữ bậc"))) -> Lần đầu đúng → 3 ngày
A4: 1 | B4: 1 | C4: 3 | D4: Q03 | E4: Mới | F4: — | G4: =IF(F4="—","—",(LEN(F4)-LEN(SUBSTITUTE(F4,"S",""))+1)/(LEN(F4)+2)) -> — | H4: — | I4: — | J4: =IF(H4="—","—",'Quy tac'!$B$5^(I4/H4)) -> — | K4: =IF(H4="—","Câu mới",IF(I4>=H4,"Có","Chưa")) -> Câu mới | L4: Sai | M4: =RIGHT(IF(F4="—","",F4)&IF(L4="Đúng","Đ","S"),'Quy tac'!$B$7) -> S | N4: =(LEN(M4)-LEN(SUBSTITUTE(M4,"S",""))+1)/(LEN(M4)+2) -> 0.66666667 | O4: =IF(H4="—",IF(L4="Đúng",INDEX('Quy tac'!$B$17:$B$22,2),INDEX('Quy tac'!$B$17:$B$22,1)),IF(L4="Sai",INDEX('Quy tac'!$B$17:$B$22,1),IF(I4>=H4,INDEX('Quy tac'!$B$17:$B$22,MIN(MATCH(H4,'Quy tac'!$B$17:$B$22,0)+1,6)),H4))) -> 1 | P4: =B4+O4 -> 2 | Q4: =IF(H4="—",IF(L4="Đúng","Lần đầu đúng → 3 ngày","Lần đầu sai → 1 ngày"),IF(L4="Sai","Sai → về 1 ngày",IF(I4>=H4,"Đúng, đến hạn → lên 1 bậc","Đúng nhưng ôn sớm → giữ bậc"))) -> Lần đầu sai → 1 ngày
A5: 1 | B5: 1 | C5: 4 | D5: Q04 | E5: Mới | F5: — | G5: =IF(F5="—","—",(LEN(F5)-LEN(SUBSTITUTE(F5,"S",""))+1)/(LEN(F5)+2)) -> — | H5: — | I5: — | J5: =IF(H5="—","—",'Quy tac'!$B$5^(I5/H5)) -> — | K5: =IF(H5="—","Câu mới",IF(I5>=H5,"Có","Chưa")) -> Câu mới | L5: Đúng | M5: =RIGHT(IF(F5="—","",F5)&IF(L5="Đúng","Đ","S"),'Quy tac'!$B$7) -> Đ | N5: =(LEN(M5)-LEN(SUBSTITUTE(M5,"S",""))+1)/(LEN(M5)+2) -> 0.33333333 | O5: =IF(H5="—",IF(L5="Đúng",INDEX('Quy tac'!$B$17:$B$22,2),INDEX('Quy tac'!$B$17:$B$22,1)),IF(L5="Sai",INDEX('Quy tac'!$B$17:$B$22,1),IF(I5>=H5,INDEX('Quy tac'!$B$17:$B$22,MIN(MATCH(H5,'Quy tac'!$B$17:$B$22,0)+1,6)),H5))) -> 3 | P5: =B5+O5 -> 4 | Q5: =IF(H5="—",IF(L5="Đúng","Lần đầu đúng → 3 ngày","Lần đầu sai → 1 ngày"),IF(L5="Sai","Sai → về 1 ngày",IF(I5>=H5,"Đúng, đến hạn → lên 1 bậc","Đúng nhưng ôn sớm → giữ bậc"))) -> Lần đầu đúng → 3 ngày
A6: 1 | B6: 1 | C6: 5 | D6: Q05 | E6: Mới | F6: — | G6: =IF(F6="—","—",(LEN(F6)-LEN(SUBSTITUTE(F6,"S",""))+1)/(LEN(F6)+2)) -> — | H6: — | I6: — | J6: =IF(H6="—","—",'Quy tac'!$B$5^(I6/H6)) -> — | K6: =IF(H6="—","Câu mới",IF(I6>=H6,"Có","Chưa")) -> Câu mới | L6: Sai | M6: =RIGHT(IF(F6="—","",F6)&IF(L6="Đúng","Đ","S"),'Quy tac'!$B$7) -> S | N6: =(LEN(M6)-LEN(SUBSTITUTE(M6,"S",""))+1)/(LEN(M6)+2) -> 0.66666667 | O6: =IF(H6="—",IF(L6="Đúng",INDEX('Quy tac'!$B$17:$B$22,2),INDEX('Quy tac'!$B$17:$B$22,1)),IF(L6="Sai",INDEX('Quy tac'!$B$17:$B$22,1),IF(I6>=H6,INDEX('Quy tac'!$B$17:$B$22,MIN(MATCH(H6,'Quy tac'!$B$17:$B$22,0)+1,6)),H6))) -> 1 | P6: =B6+O6 -> 2 | Q6: =IF(H6="—",IF(L6="Đúng","Lần đầu đúng → 3 ngày","Lần đầu sai → 1 ngày"),IF(L6="Sai","Sai → về 1 ngày",IF(I6>=H6,"Đúng, đến hạn → lên 1 bậc","Đúng nhưng ôn sớm → giữ bậc"))) -> Lần đầu sai → 1 ngày
A7: 1 | B7: 1 | C7: 6 | D7: Q06 | E7: Mới | F7: — | G7: =IF(F7="—","—",(LEN(F7)-LEN(SUBSTITUTE(F7,"S",""))+1)/(LEN(F7)+2)) -> — | H7: — | I7: — | J7: =IF(H7="—","—",'Quy tac'!$B$5^(I7/H7)) -> — | K7: =IF(H7="—","Câu mới",IF(I7>=H7,"Có","Chưa")) -> Câu mới | L7: Đúng | M7: =RIGHT(IF(F7="—","",F7)&IF(L7="Đúng","Đ","S"),'Quy tac'!$B$7) -> Đ | N7: =(LEN(M7)-LEN(SUBSTITUTE(M7,"S",""))+1)/(LEN(M7)+2) -> 0.33333333 | O7: =IF(H7="—",IF(L7="Đúng",INDEX('Quy tac'!$B$17:$B$22,2),INDEX('Quy tac'!$B$17:$B$22,1)),IF(L7="Sai",INDEX('Quy tac'!$B$17:$B$22,1),IF(I7>=H7,INDEX('Quy tac'!$B$17:$B$22,MIN(MATCH(H7,'Quy tac'!$B$17:$B$22,0)+1,6)),H7))) -> 3 | P7: =B7+O7 -> 4 | Q7: =IF(H7="—",IF(L7="Đúng","Lần đầu đúng → 3 ngày","Lần đầu sai → 1 ngày"),IF(L7="Sai","Sai → về 1 ngày",IF(I7>=H7,"Đúng, đến hạn → lên 1 bậc","Đúng nhưng ôn sớm → giữ bậc"))) -> Lần đầu đúng → 3 ngày
A8: 1 | B8: 1 | C8: 7 | D8: Q07 | E8: Mới | F8: — | G8: =IF(F8="—","—",(LEN(F8)-LEN(SUBSTITUTE(F8,"S",""))+1)/(LEN(F8)+2)) -> — | H8: — | I8: — | J8: =IF(H8="—","—",'Quy tac'!$B$5^(I8/H8)) -> — | K8: =IF(H8="—","Câu mới",IF(I8>=H8,"Có","Chưa")) -> Câu mới | L8: Đúng | M8: =RIGHT(IF(F8="—","",F8)&IF(L8="Đúng","Đ","S"),'Quy tac'!$B$7) -> Đ | N8: =(LEN(M8)-LEN(SUBSTITUTE(M8,"S",""))+1)/(LEN(M8)+2) -> 0.33333333 | O8: =IF(H8="—",IF(L8="Đúng",INDEX('Quy tac'!$B$17:$B$22,2),INDEX('Quy tac'!$B$17:$B$22,1)),IF(L8="Sai",INDEX('Quy tac'!$B$17:$B$22,1),IF(I8>=H8,INDEX('Quy tac'!$B$17:$B$22,MIN(MATCH(H8,'Quy tac'!$B$17:$B$22,0)+1,6)),H8))) -> 3 | P8: =B8+O8 -> 4 | Q8: =IF(H8="—",IF(L8="Đúng","Lần đầu đúng → 3 ngày","Lần đầu sai → 1 ngày"),IF(L8="Sai","Sai → về 1 ngày",IF(I8>=H8,"Đúng, đến hạn → lên 1 bậc","Đúng nhưng ôn sớm → giữ bậc"))) -> Lần đầu đúng → 3 ngày
A9: 1 | B9: 1 | C9: 8 | D9: Q08 | E9: Mới | F9: — | G9: =IF(F9="—","—",(LEN(F9)-LEN(SUBSTITUTE(F9,"S",""))+1)/(LEN(F9)+2)) -> — | H9: — | I9: — | J9: =IF(H9="—","—",'Quy tac'!$B$5^(I9/H9)) -> — | K9: =IF(H9="—","Câu mới",IF(I9>=H9,"Có","Chưa")) -> Câu mới | L9: Đúng | M9: =RIGHT(IF(F9="—","",F9)&IF(L9="Đúng","Đ","S"),'Quy tac'!$B$7) -> Đ | N9: =(LEN(M9)-LEN(SUBSTITUTE(M9,"S",""))+1)/(LEN(M9)+2) -> 0.33333333 | O9: =IF(H9="—",IF(L9="Đúng",INDEX('Quy tac'!$B$17:$B$22,2),INDEX('Quy tac'!$B$17:$B$22,1)),IF(L9="Sai",INDEX('Quy tac'!$B$17:$B$22,1),IF(I9>=H9,INDEX('Quy tac'!$B$17:$B$22,MIN(MATCH(H9,'Quy tac'!$B$17:$B$22,0)+1,6)),H9))) -> 3 | P9: =B9+O9 -> 4 | Q9: =IF(H9="—",IF(L9="Đúng","Lần đầu đúng → 3 ngày","Lần đầu sai → 1 ngày"),IF(L9="Sai","Sai → về 1 ngày",IF(I9>=H9,"Đúng, đến hạn → lên 1 bậc","Đúng nhưng ôn sớm → giữ bậc"))) -> Lần đầu đúng → 3 ngày
A10: 1 | B10: 1 | C10: 9 | D10: Q09 | E10: Mới | F10: — | G10: =IF(F10="—","—",(LEN(F10)-LEN(SUBSTITUTE(F10,"S",""))+1)/(LEN(F10)+2)) -> — | H10: — | I10: — | J10: =IF(H10="—","—",'Quy tac'!$B$5^(I10/H10)) -> — | K10: =IF(H10="—","Câu mới",IF(I10>=H10,"Có","Chưa")) -> Câu mới | L10: Đúng | M10: =RIGHT(IF(F10="—","",F10)&IF(L10="Đúng","Đ","S"),'Quy tac'!$B$7) -> Đ | N10: =(LEN(M10)-LEN(SUBSTITUTE(M10,"S",""))+1)/(LEN(M10)+2) -> 0.33333333 | O10: =IF(H10="—",IF(L10="Đúng",INDEX('Quy tac'!$B$17:$B$22,2),INDEX('Quy tac'!$B$17:$B$22,1)),IF(L10="Sai",INDEX('Quy tac'!$B$17:$B$22,1),IF(I10>=H10,INDEX('Quy tac'!$B$17:$B$22,MIN(MATCH(H10,'Quy tac'!$B$17:$B$22,0)+1,6)),H10))) -> 3 | P10: =B10+O10 -> 4 | Q10: =IF(H10="—",IF(L10="Đúng","Lần đầu đúng → 3 ngày","Lần đầu sai → 1 ngày"),IF(L10="Sai","Sai → về 1 ngày",IF(I10>=H10,"Đúng, đến hạn → lên 1 bậc","Đúng nhưng ôn sớm → giữ bậc"))) -> Lần đầu đúng → 3 ngày
A11: 1 | B11: 1 | C11: 10 | D11: Q10 | E11: Mới | F11: — | G11: =IF(F11="—","—",(LEN(F11)-LEN(SUBSTITUTE(F11,"S",""))+1)/(LEN(F11)+2)) -> — | H11: — | I11: — | J11: =IF(H11="—","—",'Quy tac'!$B$5^(I11/H11)) -> — | K11: =IF(H11="—","Câu mới",IF(I11>=H11,"Có","Chưa")) -> Câu mới | L11: Sai | M11: =RIGHT(IF(F11="—","",F11)&IF(L11="Đúng","Đ","S"),'Quy tac'!$B$7) -> S | N11: =(LEN(M11)-LEN(SUBSTITUTE(M11,"S",""))+1)/(LEN(M11)+2) -> 0.66666667 | O11: =IF(H11="—",IF(L11="Đúng",INDEX('Quy tac'!$B$17:$B$22,2),INDEX('Quy tac'!$B$17:$B$22,1)),IF(L11="Sai",INDEX('Quy tac'!$B$17:$B$22,1),IF(I11>=H11,INDEX('Quy tac'!$B$17:$B$22,MIN(MATCH(H11,'Quy tac'!$B$17:$B$22,0)+1,6)),H11))) -> 1 | P11: =B11+O11 -> 2 | Q11: =IF(H11="—",IF(L11="Đúng","Lần đầu đúng → 3 ngày","Lần đầu sai → 1 ngày"),IF(L11="Sai","Sai → về 1 ngày",IF(I11>=H11,"Đúng, đến hạn → lên 1 bậc","Đúng nhưng ôn sớm → giữ bậc"))) -> Lần đầu sai → 1 ngày
A12: 2 | B12: 2 | C12: 1 | D12: Q03 | E12: Yếu | F12: S | G12: =IF(F12="—","—",(LEN(F12)-LEN(SUBSTITUTE(F12,"S",""))+1)/(LEN(F12)+2)) -> 0.66666667 | H12: 1 | I12: 1 | J12: =IF(H12="—","—",'Quy tac'!$B$5^(I12/H12)) -> 0.9 | K12: =IF(H12="—","Câu mới",IF(I12>=H12,"Có","Chưa")) -> Có | L12: Sai | M12: =RIGHT(IF(F12="—","",F12)&IF(L12="Đúng","Đ","S"),'Quy tac'!$B$7) -> SS | N12: =(LEN(M12)-LEN(SUBSTITUTE(M12,"S",""))+1)/(LEN(M12)+2) -> 0.75 | O12: =IF(H12="—",IF(L12="Đúng",INDEX('Quy tac'!$B$17:$B$22,2),INDEX('Quy tac'!$B$17:$B$22,1)),IF(L12="Sai",INDEX('Quy tac'!$B$17:$B$22,1),IF(I12>=H12,INDEX('Quy tac'!$B$17:$B$22,MIN(MATCH(H12,'Quy tac'!$B$17:$B$22,0)+1,6)),H12))) -> 1 | P12: =B12+O12 -> 3 | Q12: =IF(H12="—",IF(L12="Đúng","Lần đầu đúng → 3 ngày","Lần đầu sai → 1 ngày"),IF(L12="Sai","Sai → về 1 ngày",IF(I12>=H12,"Đúng, đến hạn → lên 1 bậc","Đúng nhưng ôn sớm → giữ bậc"))) -> Sai → về 1 ngày
A13: 2 | B13: 2 | C13: 2 | D13: Q05 | E13: Yếu | F13: S | G13: =IF(F13="—","—",(LEN(F13)-LEN(SUBSTITUTE(F13,"S",""))+1)/(LEN(F13)+2)) -> 0.66666667 | H13: 1 | I13: 1 | J13: =IF(H13="—","—",'Quy tac'!$B$5^(I13/H13)) -> 0.9 | K13: =IF(H13="—","Câu mới",IF(I13>=H13,"Có","Chưa")) -> Có | L13: Đúng | M13: =RIGHT(IF(F13="—","",F13)&IF(L13="Đúng","Đ","S"),'Quy tac'!$B$7) -> SĐ | N13: =(LEN(M13)-LEN(SUBSTITUTE(M13,"S",""))+1)/(LEN(M13)+2) -> 0.5 | O13: =IF(H13="—",IF(L13="Đúng",INDEX('Quy tac'!$B$17:$B$22,2),INDEX('Quy tac'!$B$17:$B$22,1)),IF(L13="Sai",INDEX('Quy tac'!$B$17:$B$22,1),IF(I13>=H13,INDEX('Quy tac'!$B$17:$B$22,MIN(MATCH(H13,'Quy tac'!$B$17:$B$22,0)+1,6)),H13))) -> 3 | P13: =B13+O13 -> 5 | Q13: =IF(H13="—",IF(L13="Đúng","Lần đầu đúng → 3 ngày","Lần đầu sai → 1 ngày"),IF(L13="Sai","Sai → về 1 ngày",IF(I13>=H13,"Đúng, đến hạn → lên 1 bậc","Đúng nhưng ôn sớm → giữ bậc"))) -> Đúng, đến hạn → lên 1 bậc
A14: 2 | B14: 2 | C14: 3 | D14: Q10 | E14: Yếu | F14: S | G14: =IF(F14="—","—",(LEN(F14)-LEN(SUBSTITUTE(F14,"S",""))+1)/(LEN(F14)+2)) -> 0.66666667 | H14: 1 | I14: 1 | J14: =IF(H14="—","—",'Quy tac'!$B$5^(I14/H14)) -> 0.9 | K14: =IF(H14="—","Câu mới",IF(I14>=H14,"Có","Chưa")) -> Có | L14: Đúng | M14: =RIGHT(IF(F14="—","",F14)&IF(L14="Đúng","Đ","S"),'Quy tac'!$B$7) -> SĐ | N14: =(LEN(M14)-LEN(SUBSTITUTE(M14,"S",""))+1)/(LEN(M14)+2) -> 0.5 | O14: =IF(H14="—",IF(L14="Đúng",INDEX('Quy tac'!$B$17:$B$22,2),INDEX('Quy tac'!$B$17:$B$22,1)),IF(L14="Sai",INDEX('Quy tac'!$B$17:$B$22,1),IF(I14>=H14,INDEX('Quy tac'!$B$17:$B$22,MIN(MATCH(H14,'Quy tac'!$B$17:$B$22,0)+1,6)),H14))) -> 3 | P14: =B14+O14 -> 5 | Q14: =IF(H14="—",IF(L14="Đúng","Lần đầu đúng → 3 ngày","Lần đầu sai → 1 ngày"),IF(L14="Sai","Sai → về 1 ngày",IF(I14>=H14,"Đúng, đến hạn → lên 1 bậc","Đúng nhưng ôn sớm → giữ bậc"))) -> Đúng, đến hạn → lên 1 bậc
A15: 2 | B15: 2 | C15: 4 | D15: Q11 | E15: Mới | F15: — | G15: =IF(F15="—","—",(LEN(F15)-LEN(SUBSTITUTE(F15,"S",""))+1)/(LEN(F15)+2)) -> — | H15: — | I15: — | J15: =IF(H15="—","—",'Quy tac'!$B$5^(I15/H15)) -> — | K15: =IF(H15="—","Câu mới",IF(I15>=H15,"Có","Chưa")) -> Câu mới | L15: Đúng | M15: =RIGHT(IF(F15="—","",F15)&IF(L15="Đúng","Đ","S"),'Quy tac'!$B$7) -> Đ | N15: =(LEN(M15)-LEN(SUBSTITUTE(M15,"S",""))+1)/(LEN(M15)+2) -> 0.33333333 | O15: =IF(H15="—",IF(L15="Đúng",INDEX('Quy tac'!$B$17:$B$22,2),INDEX('Quy tac'!$B$17:$B$22,1)),IF(L15="Sai",INDEX('Quy tac'!$B$17:$B$22,1),IF(I15>=H15,INDEX('Quy tac'!$B$17:$B$22,MIN(MATCH(H15,'Quy tac'!$B$17:$B$22,0)+1,6)),H15))) -> 3 | P15: =B15+O15 -> 5 | Q15: =IF(H15="—",IF(L15="Đúng","Lần đầu đúng → 3 ngày","Lần đầu sai → 1 ngày"),IF(L15="Sai","Sai → về 1 ngày",IF(I15>=H15,"Đúng, đến hạn → lên 1 bậc","Đúng nhưng ôn sớm → giữ bậc"))) -> Lần đầu đúng → 3 ngày
A16: 2 | B16: 2 | C16: 5 | D16: Q12 | E16: Mới | F16: — | G16: =IF(F16="—","—",(LEN(F16)-LEN(SUBSTITUTE(F16,"S",""))+1)/(LEN(F16)+2)) -> — | H16: — | I16: — | J16: =IF(H16="—","—",'Quy tac'!$B$5^(I16/H16)) -> — | K16: =IF(H16="—","Câu mới",IF(I16>=H16,"Có","Chưa")) -> Câu mới | L16: Đúng | M16: =RIGHT(IF(F16="—","",F16)&IF(L16="Đúng","Đ","S"),'Quy tac'!$B$7) -> Đ | N16: =(LEN(M16)-LEN(SUBSTITUTE(M16,"S",""))+1)/(LEN(M16)+2) -> 0.33333333 | O16: =IF(H16="—",IF(L16="Đúng",INDEX('Quy tac'!$B$17:$B$22,2),INDEX('Quy tac'!$B$17:$B$22,1)),IF(L16="Sai",INDEX('Quy tac'!$B$17:$B$22,1),IF(I16>=H16,INDEX('Quy tac'!$B$17:$B$22,MIN(MATCH(H16,'Quy tac'!$B$17:$B$22,0)+1,6)),H16))) -> 3 | P16: =B16+O16 -> 5 | Q16: =IF(H16="—",IF(L16="Đúng","Lần đầu đúng → 3 ngày","Lần đầu sai → 1 ngày"),IF(L16="Sai","Sai → về 1 ngày",IF(I16>=H16,"Đúng, đến hạn → lên 1 bậc","Đúng nhưng ôn sớm → giữ bậc"))) -> Lần đầu đúng → 3 ngày
A17: 2 | B17: 2 | C17: 6 | D17: Q13 | E17: Mới | F17: — | G17: =IF(F17="—","—",(LEN(F17)-LEN(SUBSTITUTE(F17,"S",""))+1)/(LEN(F17)+2)) -> — | H17: — | I17: — | J17: =IF(H17="—","—",'Quy tac'!$B$5^(I17/H17)) -> — | K17: =IF(H17="—","Câu mới",IF(I17>=H17,"Có","Chưa")) -> Câu mới | L17: Đúng | M17: =RIGHT(IF(F17="—","",F17)&IF(L17="Đúng","Đ","S"),'Quy tac'!$B$7) -> Đ | N17: =(LEN(M17)-LEN(SUBSTITUTE(M17,"S",""))+1)/(LEN(M17)+2) -> 0.33333333 | O17: =IF(H17="—",IF(L17="Đúng",INDEX('Quy tac'!$B$17:$B$22,2),INDEX('Quy tac'!$B$17:$B$22,1)),IF(L17="Sai",INDEX('Quy tac'!$B$17:$B$22,1),IF(I17>=H17,INDEX('Quy tac'!$B$17:$B$22,MIN(MATCH(H17,'Quy tac'!$B$17:$B$22,0)+1,6)),H17))) -> 3 | P17: =B17+O17 -> 5 | Q17: =IF(H17="—",IF(L17="Đúng","Lần đầu đúng → 3 ngày","Lần đầu sai → 1 ngày"),IF(L17="Sai","Sai → về 1 ngày",IF(I17>=H17,"Đúng, đến hạn → lên 1 bậc","Đúng nhưng ôn sớm → giữ bậc"))) -> Lần đầu đúng → 3 ngày
A18: 2 | B18: 2 | C18: 7 | D18: Q14 | E18: Mới | F18: — | G18: =IF(F18="—","—",(LEN(F18)-LEN(SUBSTITUTE(F18,"S",""))+1)/(LEN(F18)+2)) -> — | H18: — | I18: — | J18: =IF(H18="—","—",'Quy tac'!$B$5^(I18/H18)) -> — | K18: =IF(H18="—","Câu mới",IF(I18>=H18,"Có","Chưa")) -> Câu mới | L18: Sai | M18: =RIGHT(IF(F18="—","",F18)&IF(L18="Đúng","Đ","S"),'Quy tac'!$B$7) -> S | N18: =(LEN(M18)-LEN(SUBSTITUTE(M18,"S",""))+1)/(LEN(M18)+2) -> 0.66666667 | O18: =IF(H18="—",IF(L18="Đúng",INDEX('Quy tac'!$B$17:$B$22,2),INDEX('Quy tac'!$B$17:$B$22,1)),IF(L18="Sai",INDEX('Quy tac'!$B$17:$B$22,1),IF(I18>=H18,INDEX('Quy tac'!$B$17:$B$22,MIN(MATCH(H18,'Quy tac'!$B$17:$B$22,0)+1,6)),H18))) -> 1 | P18: =B18+O18 -> 3 | Q18: =IF(H18="—",IF(L18="Đúng","Lần đầu đúng → 3 ngày","Lần đầu sai → 1 ngày"),IF(L18="Sai","Sai → về 1 ngày",IF(I18>=H18,"Đúng, đến hạn → lên 1 bậc","Đúng nhưng ôn sớm → giữ bậc"))) -> Lần đầu sai → 1 ngày
A19: 2 | B19: 2 | C19: 8 | D19: Q15 | E19: Mới | F19: — | G19: =IF(F19="—","—",(LEN(F19)-LEN(SUBSTITUTE(F19,"S",""))+1)/(LEN(F19)+2)) -> — | H19: — | I19: — | J19: =IF(H19="—","—",'Quy tac'!$B$5^(I19/H19)) -> — | K19: =IF(H19="—","Câu mới",IF(I19>=H19,"Có","Chưa")) -> Câu mới | L19: Sai | M19: =RIGHT(IF(F19="—","",F19)&IF(L19="Đúng","Đ","S"),'Quy tac'!$B$7) -> S | N19: =(LEN(M19)-LEN(SUBSTITUTE(M19,"S",""))+1)/(LEN(M19)+2) -> 0.66666667 | O19: =IF(H19="—",IF(L19="Đúng",INDEX('Quy tac'!$B$17:$B$22,2),INDEX('Quy tac'!$B$17:$B$22,1)),IF(L19="Sai",INDEX('Quy tac'!$B$17:$B$22,1),IF(I19>=H19,INDEX('Quy tac'!$B$17:$B$22,MIN(MATCH(H19,'Quy tac'!$B$17:$B$22,0)+1,6)),H19))) -> 1 | P19: =B19+O19 -> 3 | Q19: =IF(H19="—",IF(L19="Đúng","Lần đầu đúng → 3 ngày","Lần đầu sai → 1 ngày"),IF(L19="Sai","Sai → về 1 ngày",IF(I19>=H19,"Đúng, đến hạn → lên 1 bậc","Đúng nhưng ôn sớm → giữ bậc"))) -> Lần đầu sai → 1 ngày
A20: 2 | B20: 2 | C20: 9 | D20: Q16 | E20: Mới | F20: — | G20: =IF(F20="—","—",(LEN(F20)-LEN(SUBSTITUTE(F20,"S",""))+1)/(LEN(F20)+2)) -> — | H20: — | I20: — | J20: =IF(H20="—","—",'Quy tac'!$B$5^(I20/H20)) -> — | K20: =IF(H20="—","Câu mới",IF(I20>=H20,"Có","Chưa")) -> Câu mới | L20: Đúng | M20: =RIGHT(IF(F20="—","",F20)&IF(L20="Đúng","Đ","S"),'Quy tac'!$B$7) -> Đ | N20: =(LEN(M20)-LEN(SUBSTITUTE(M20,"S",""))+1)/(LEN(M20)+2) -> 0.33333333 | O20: =IF(H20="—",IF(L20="Đúng",INDEX('Quy tac'!$B$17:$B$22,2),INDEX('Quy tac'!$B$17:$B$22,1)),IF(L20="Sai",INDEX('Quy tac'!$B$17:$B$22,1),IF(I20>=H20,INDEX('Quy tac'!$B$17:$B$22,MIN(MATCH(H20,'Quy tac'!$B$17:$B$22,0)+1,6)),H20))) -> 3 | P20: =B20+O20 -> 5 | Q20: =IF(H20="—",IF(L20="Đúng","Lần đầu đúng → 3 ngày","Lần đầu sai → 1 ngày"),IF(L20="Sai","Sai → về 1 ngày",IF(I20>=H20,"Đúng, đến hạn → lên 1 bậc","Đúng nhưng ôn sớm → giữ bậc"))) -> Lần đầu đúng → 3 ngày
A21: 2 | B21: 2 | C21: 10 | D21: Q17 | E21: Mới | F21: — | G21: =IF(F21="—","—",(LEN(F21)-LEN(SUBSTITUTE(F21,"S",""))+1)/(LEN(F21)+2)) -> — | H21: — | I21: — | J21: =IF(H21="—","—",'Quy tac'!$B$5^(I21/H21)) -> — | K21: =IF(H21="—","Câu mới",IF(I21>=H21,"Có","Chưa")) -> Câu mới | L21: Sai | M21: =RIGHT(IF(F21="—","",F21)&IF(L21="Đúng","Đ","S"),'Quy tac'!$B$7) -> S | N21: =(LEN(M21)-LEN(SUBSTITUTE(M21,"S",""))+1)/(LEN(M21)+2) -> 0.66666667 | O21: =IF(H21="—",IF(L21="Đúng",INDEX('Quy tac'!$B$17:$B$22,2),INDEX('Quy tac'!$B$17:$B$22,1)),IF(L21="Sai",INDEX('Quy tac'!$B$17:$B$22,1),IF(I21>=H21,INDEX('Quy tac'!$B$17:$B$22,MIN(MATCH(H21,'Quy tac'!$B$17:$B$22,0)+1,6)),H21))) -> 1 | P21: =B21+O21 -> 3 | Q21: =IF(H21="—",IF(L21="Đúng","Lần đầu đúng → 3 ngày","Lần đầu sai → 1 ngày"),IF(L21="Sai","Sai → về 1 ngày",IF(I21>=H21,"Đúng, đến hạn → lên 1 bậc","Đúng nhưng ôn sớm → giữ bậc"))) -> Lần đầu sai → 1 ngày
A22: 3 | B22: 3 | C22: 1 | D22: Q03 | E22: Yếu | F22: SS | G22: =IF(F22="—","—",(LEN(F22)-LEN(SUBSTITUTE(F22,"S",""))+1)/(LEN(F22)+2)) -> 0.75 | H22: 1 | I22: 1 | J22: =IF(H22="—","—",'Quy tac'!$B$5^(I22/H22)) -> 0.9 | K22: =IF(H22="—","Câu mới",IF(I22>=H22,"Có","Chưa")) -> Có | L22: Sai | M22: =RIGHT(IF(F22="—","",F22)&IF(L22="Đúng","Đ","S"),'Quy tac'!$B$7) -> SSS | N22: =(LEN(M22)-LEN(SUBSTITUTE(M22,"S",""))+1)/(LEN(M22)+2) -> 0.8 | O22: =IF(H22="—",IF(L22="Đúng",INDEX('Quy tac'!$B$17:$B$22,2),INDEX('Quy tac'!$B$17:$B$22,1)),IF(L22="Sai",INDEX('Quy tac'!$B$17:$B$22,1),IF(I22>=H22,INDEX('Quy tac'!$B$17:$B$22,MIN(MATCH(H22,'Quy tac'!$B$17:$B$22,0)+1,6)),H22))) -> 1 | P22: =B22+O22 -> 4 | Q22: =IF(H22="—",IF(L22="Đúng","Lần đầu đúng → 3 ngày","Lần đầu sai → 1 ngày"),IF(L22="Sai","Sai → về 1 ngày",IF(I22>=H22,"Đúng, đến hạn → lên 1 bậc","Đúng nhưng ôn sớm → giữ bậc"))) -> Sai → về 1 ngày
A23: 3 | B23: 3 | C23: 2 | D23: Q14 | E23: Yếu | F23: S | G23: =IF(F23="—","—",(LEN(F23)-LEN(SUBSTITUTE(F23,"S",""))+1)/(LEN(F23)+2)) -> 0.66666667 | H23: 1 | I23: 1 | J23: =IF(H23="—","—",'Quy tac'!$B$5^(I23/H23)) -> 0.9 | K23: =IF(H23="—","Câu mới",IF(I23>=H23,"Có","Chưa")) -> Có | L23: Sai | M23: =RIGHT(IF(F23="—","",F23)&IF(L23="Đúng","Đ","S"),'Quy tac'!$B$7) -> SS | N23: =(LEN(M23)-LEN(SUBSTITUTE(M23,"S",""))+1)/(LEN(M23)+2) -> 0.75 | O23: =IF(H23="—",IF(L23="Đúng",INDEX('Quy tac'!$B$17:$B$22,2),INDEX('Quy tac'!$B$17:$B$22,1)),IF(L23="Sai",INDEX('Quy tac'!$B$17:$B$22,1),IF(I23>=H23,INDEX('Quy tac'!$B$17:$B$22,MIN(MATCH(H23,'Quy tac'!$B$17:$B$22,0)+1,6)),H23))) -> 1 | P23: =B23+O23 -> 4 | Q23: =IF(H23="—",IF(L23="Đúng","Lần đầu đúng → 3 ngày","Lần đầu sai → 1 ngày"),IF(L23="Sai","Sai → về 1 ngày",IF(I23>=H23,"Đúng, đến hạn → lên 1 bậc","Đúng nhưng ôn sớm → giữ bậc"))) -> Sai → về 1 ngày
A24: 3 | B24: 3 | C24: 3 | D24: Q15 | E24: Yếu | F24: S | G24: =IF(F24="—","—",(LEN(F24)-LEN(SUBSTITUTE(F24,"S",""))+1)/(LEN(F24)+2)) -> 0.66666667 | H24: 1 | I24: 1 | J24: =IF(H24="—","—",'Quy tac'!$B$5^(I24/H24)) -> 0.9 | K24: =IF(H24="—","Câu mới",IF(I24>=H24,"Có","Chưa")) -> Có | L24: Đúng | M24: =RIGHT(IF(F24="—","",F24)&IF(L24="Đúng","Đ","S"),'Quy tac'!$B$7) -> SĐ | N24: =(LEN(M24)-LEN(SUBSTITUTE(M24,"S",""))+1)/(LEN(M24)+2) -> 0.5 | O24: =IF(H24="—",IF(L24="Đúng",INDEX('Quy tac'!$B$17:$B$22,2),INDEX('Quy tac'!$B$17:$B$22,1)),IF(L24="Sai",INDEX('Quy tac'!$B$17:$B$22,1),IF(I24>=H24,INDEX('Quy tac'!$B$17:$B$22,MIN(MATCH(H24,'Quy tac'!$B$17:$B$22,0)+1,6)),H24))) -> 3 | P24: =B24+O24 -> 6 | Q24: =IF(H24="—",IF(L24="Đúng","Lần đầu đúng → 3 ngày","Lần đầu sai → 1 ngày"),IF(L24="Sai","Sai → về 1 ngày",IF(I24>=H24,"Đúng, đến hạn → lên 1 bậc","Đúng nhưng ôn sớm → giữ bậc"))) -> Đúng, đến hạn → lên 1 bậc
A25: 3 | B25: 3 | C25: 4 | D25: Q17 | E25: Yếu | F25: S | G25: =IF(F25="—","—",(LEN(F25)-LEN(SUBSTITUTE(F25,"S",""))+1)/(LEN(F25)+2)) -> 0.66666667 | H25: 1 | I25: 1 | J25: =IF(H25="—","—",'Quy tac'!$B$5^(I25/H25)) -> 0.9 | K25: =IF(H25="—","Câu mới",IF(I25>=H25,"Có","Chưa")) -> Có | L25: Sai | M25: =RIGHT(IF(F25="—","",F25)&IF(L25="Đúng","Đ","S"),'Quy tac'!$B$7) -> SS | N25: =(LEN(M25)-LEN(SUBSTITUTE(M25,"S",""))+1)/(LEN(M25)+2) -> 0.75 | O25: =IF(H25="—",IF(L25="Đúng",INDEX('Quy tac'!$B$17:$B$22,2),INDEX('Quy tac'!$B$17:$B$22,1)),IF(L25="Sai",INDEX('Quy tac'!$B$17:$B$22,1),IF(I25>=H25,INDEX('Quy tac'!$B$17:$B$22,MIN(MATCH(H25,'Quy tac'!$B$17:$B$22,0)+1,6)),H25))) -> 1 | P25: =B25+O25 -> 4 | Q25: =IF(H25="—",IF(L25="Đúng","Lần đầu đúng → 3 ngày","Lần đầu sai → 1 ngày"),IF(L25="Sai","Sai → về 1 ngày",IF(I25>=H25,"Đúng, đến hạn → lên 1 bậc","Đúng nhưng ôn sớm → giữ bậc"))) -> Sai → về 1 ngày
A26: 3 | B26: 3 | C26: 5 | D26: Q05 | E26: Yếu | F26: SĐ | G26: =IF(F26="—","—",(LEN(F26)-LEN(SUBSTITUTE(F26,"S",""))+1)/(LEN(F26)+2)) -> 0.5 | H26: 3 | I26: 1 | J26: =IF(H26="—","—",'Quy tac'!$B$5^(I26/H26)) -> 0.96548938 | K26: =IF(H26="—","Câu mới",IF(I26>=H26,"Có","Chưa")) -> Chưa | L26: Sai | M26: =RIGHT(IF(F26="—","",F26)&IF(L26="Đúng","Đ","S"),'Quy tac'!$B$7) -> SĐS | N26: =(LEN(M26)-LEN(SUBSTITUTE(M26,"S",""))+1)/(LEN(M26)+2) -> 0.6 | O26: =IF(H26="—",IF(L26="Đúng",INDEX('Quy tac'!$B$17:$B$22,2),INDEX('Quy tac'!$B$17:$B$22,1)),IF(L26="Sai",INDEX('Quy tac'!$B$17:$B$22,1),IF(I26>=H26,INDEX('Quy tac'!$B$17:$B$22,MIN(MATCH(H26,'Quy tac'!$B$17:$B$22,0)+1,6)),H26))) -> 1 | P26: =B26+O26 -> 4 | Q26: =IF(H26="—",IF(L26="Đúng","Lần đầu đúng → 3 ngày","Lần đầu sai → 1 ngày"),IF(L26="Sai","Sai → về 1 ngày",IF(I26>=H26,"Đúng, đến hạn → lên 1 bậc","Đúng nhưng ôn sớm → giữ bậc"))) -> Sai → về 1 ngày
A27: 3 | B27: 3 | C27: 6 | D27: Q10 | E27: Yếu | F27: SĐ | G27: =IF(F27="—","—",(LEN(F27)-LEN(SUBSTITUTE(F27,"S",""))+1)/(LEN(F27)+2)) -> 0.5 | H27: 3 | I27: 1 | J27: =IF(H27="—","—",'Quy tac'!$B$5^(I27/H27)) -> 0.96548938 | K27: =IF(H27="—","Câu mới",IF(I27>=H27,"Có","Chưa")) -> Chưa | L27: Đúng | M27: =RIGHT(IF(F27="—","",F27)&IF(L27="Đúng","Đ","S"),'Quy tac'!$B$7) -> SĐĐ | N27: =(LEN(M27)-LEN(SUBSTITUTE(M27,"S",""))+1)/(LEN(M27)+2) -> 0.4 | O27: =IF(H27="—",IF(L27="Đúng",INDEX('Quy tac'!$B$17:$B$22,2),INDEX('Quy tac'!$B$17:$B$22,1)),IF(L27="Sai",INDEX('Quy tac'!$B$17:$B$22,1),IF(I27>=H27,INDEX('Quy tac'!$B$17:$B$22,MIN(MATCH(H27,'Quy tac'!$B$17:$B$22,0)+1,6)),H27))) -> 3 | P27: =B27+O27 -> 6 | Q27: =IF(H27="—",IF(L27="Đúng","Lần đầu đúng → 3 ngày","Lần đầu sai → 1 ngày"),IF(L27="Sai","Sai → về 1 ngày",IF(I27>=H27,"Đúng, đến hạn → lên 1 bậc","Đúng nhưng ôn sớm → giữ bậc"))) -> Đúng nhưng ôn sớm → giữ bậc
A28: 3 | B28: 3 | C28: 7 | D28: Q18 | E28: Mới | F28: — | G28: =IF(F28="—","—",(LEN(F28)-LEN(SUBSTITUTE(F28,"S",""))+1)/(LEN(F28)+2)) -> — | H28: — | I28: — | J28: =IF(H28="—","—",'Quy tac'!$B$5^(I28/H28)) -> — | K28: =IF(H28="—","Câu mới",IF(I28>=H28,"Có","Chưa")) -> Câu mới | L28: Đúng | M28: =RIGHT(IF(F28="—","",F28)&IF(L28="Đúng","Đ","S"),'Quy tac'!$B$7) -> Đ | N28: =(LEN(M28)-LEN(SUBSTITUTE(M28,"S",""))+1)/(LEN(M28)+2) -> 0.33333333 | O28: =IF(H28="—",IF(L28="Đúng",INDEX('Quy tac'!$B$17:$B$22,2),INDEX('Quy tac'!$B$17:$B$22,1)),IF(L28="Sai",INDEX('Quy tac'!$B$17:$B$22,1),IF(I28>=H28,INDEX('Quy tac'!$B$17:$B$22,MIN(MATCH(H28,'Quy tac'!$B$17:$B$22,0)+1,6)),H28))) -> 3 | P28: =B28+O28 -> 6 | Q28: =IF(H28="—",IF(L28="Đúng","Lần đầu đúng → 3 ngày","Lần đầu sai → 1 ngày"),IF(L28="Sai","Sai → về 1 ngày",IF(I28>=H28,"Đúng, đến hạn → lên 1 bậc","Đúng nhưng ôn sớm → giữ bậc"))) -> Lần đầu đúng → 3 ngày
A29: 3 | B29: 3 | C29: 8 | D29: Q19 | E29: Mới | F29: — | G29: =IF(F29="—","—",(LEN(F29)-LEN(SUBSTITUTE(F29,"S",""))+1)/(LEN(F29)+2)) -> — | H29: — | I29: — | J29: =IF(H29="—","—",'Quy tac'!$B$5^(I29/H29)) -> — | K29: =IF(H29="—","Câu mới",IF(I29>=H29,"Có","Chưa")) -> Câu mới | L29: Đúng | M29: =RIGHT(IF(F29="—","",F29)&IF(L29="Đúng","Đ","S"),'Quy tac'!$B$7) -> Đ | N29: =(LEN(M29)-LEN(SUBSTITUTE(M29,"S",""))+1)/(LEN(M29)+2) -> 0.33333333 | O29: =IF(H29="—",IF(L29="Đúng",INDEX('Quy tac'!$B$17:$B$22,2),INDEX('Quy tac'!$B$17:$B$22,1)),IF(L29="Sai",INDEX('Quy tac'!$B$17:$B$22,1),IF(I29>=H29,INDEX('Quy tac'!$B$17:$B$22,MIN(MATCH(H29,'Quy tac'!$B$17:$B$22,0)+1,6)),H29))) -> 3 | P29: =B29+O29 -> 6 | Q29: =IF(H29="—",IF(L29="Đúng","Lần đầu đúng → 3 ngày","Lần đầu sai → 1 ngày"),IF(L29="Sai","Sai → về 1 ngày",IF(I29>=H29,"Đúng, đến hạn → lên 1 bậc","Đúng nhưng ôn sớm → giữ bậc"))) -> Lần đầu đúng → 3 ngày
A30: 3 | B30: 3 | C30: 9 | D30: Q20 | E30: Mới | F30: — | G30: =IF(F30="—","—",(LEN(F30)-LEN(SUBSTITUTE(F30,"S",""))+1)/(LEN(F30)+2)) -> — | H30: — | I30: — | J30: =IF(H30="—","—",'Quy tac'!$B$5^(I30/H30)) -> — | K30: =IF(H30="—","Câu mới",IF(I30>=H30,"Có","Chưa")) -> Câu mới | L30: Đúng | M30: =RIGHT(IF(F30="—","",F30)&IF(L30="Đúng","Đ","S"),'Quy tac'!$B$7) -> Đ | N30: =(LEN(M30)-LEN(SUBSTITUTE(M30,"S",""))+1)/(LEN(M30)+2) -> 0.33333333 | O30: =IF(H30="—",IF(L30="Đúng",INDEX('Quy tac'!$B$17:$B$22,2),INDEX('Quy tac'!$B$17:$B$22,1)),IF(L30="Sai",INDEX('Quy tac'!$B$17:$B$22,1),IF(I30>=H30,INDEX('Quy tac'!$B$17:$B$22,MIN(MATCH(H30,'Quy tac'!$B$17:$B$22,0)+1,6)),H30))) -> 3 | P30: =B30+O30 -> 6 | Q30: =IF(H30="—",IF(L30="Đúng","Lần đầu đúng → 3 ngày","Lần đầu sai → 1 ngày"),IF(L30="Sai","Sai → về 1 ngày",IF(I30>=H30,"Đúng, đến hạn → lên 1 bậc","Đúng nhưng ôn sớm → giữ bậc"))) -> Lần đầu đúng → 3 ngày
A31: 3 | B31: 3 | C31: 10 | D31: Q21 | E31: Mới | F31: — | G31: =IF(F31="—","—",(LEN(F31)-LEN(SUBSTITUTE(F31,"S",""))+1)/(LEN(F31)+2)) -> — | H31: — | I31: — | J31: =IF(H31="—","—",'Quy tac'!$B$5^(I31/H31)) -> — | K31: =IF(H31="—","Câu mới",IF(I31>=H31,"Có","Chưa")) -> Câu mới | L31: Sai | M31: =RIGHT(IF(F31="—","",F31)&IF(L31="Đúng","Đ","S"),'Quy tac'!$B$7) -> S | N31: =(LEN(M31)-LEN(SUBSTITUTE(M31,"S",""))+1)/(LEN(M31)+2) -> 0.66666667 | O31: =IF(H31="—",IF(L31="Đúng",INDEX('Quy tac'!$B$17:$B$22,2),INDEX('Quy tac'!$B$17:$B$22,1)),IF(L31="Sai",INDEX('Quy tac'!$B$17:$B$22,1),IF(I31>=H31,INDEX('Quy tac'!$B$17:$B$22,MIN(MATCH(H31,'Quy tac'!$B$17:$B$22,0)+1,6)),H31))) -> 1 | P31: =B31+O31 -> 4 | Q31: =IF(H31="—",IF(L31="Đúng","Lần đầu đúng → 3 ngày","Lần đầu sai → 1 ngày"),IF(L31="Sai","Sai → về 1 ngày",IF(I31>=H31,"Đúng, đến hạn → lên 1 bậc","Đúng nhưng ôn sớm → giữ bậc"))) -> Lần đầu sai → 1 ngày
A32: 4 | B32: 4 | C32: 1 | D32: Q03 | E32: Yếu | F32: SSS | G32: =IF(F32="—","—",(LEN(F32)-LEN(SUBSTITUTE(F32,"S",""))+1)/(LEN(F32)+2)) -> 0.8 | H32: 1 | I32: 1 | J32: =IF(H32="—","—",'Quy tac'!$B$5^(I32/H32)) -> 0.9 | K32: =IF(H32="—","Câu mới",IF(I32>=H32,"Có","Chưa")) -> Có | L32: Đúng | M32: =RIGHT(IF(F32="—","",F32)&IF(L32="Đúng","Đ","S"),'Quy tac'!$B$7) -> SSSĐ | N32: =(LEN(M32)-LEN(SUBSTITUTE(M32,"S",""))+1)/(LEN(M32)+2) -> 0.66666667 | O32: =IF(H32="—",IF(L32="Đúng",INDEX('Quy tac'!$B$17:$B$22,2),INDEX('Quy tac'!$B$17:$B$22,1)),IF(L32="Sai",INDEX('Quy tac'!$B$17:$B$22,1),IF(I32>=H32,INDEX('Quy tac'!$B$17:$B$22,MIN(MATCH(H32,'Quy tac'!$B$17:$B$22,0)+1,6)),H32))) -> 3 | P32: =B32+O32 -> 7 | Q32: =IF(H32="—",IF(L32="Đúng","Lần đầu đúng → 3 ngày","Lần đầu sai → 1 ngày"),IF(L32="Sai","Sai → về 1 ngày",IF(I32>=H32,"Đúng, đến hạn → lên 1 bậc","Đúng nhưng ôn sớm → giữ bậc"))) -> Đúng, đến hạn → lên 1 bậc
A33: 4 | B33: 4 | C33: 2 | D33: Q14 | E33: Yếu | F33: SS | G33: =IF(F33="—","—",(LEN(F33)-LEN(SUBSTITUTE(F33,"S",""))+1)/(LEN(F33)+2)) -> 0.75 | H33: 1 | I33: 1 | J33: =IF(H33="—","—",'Quy tac'!$B$5^(I33/H33)) -> 0.9 | K33: =IF(H33="—","Câu mới",IF(I33>=H33,"Có","Chưa")) -> Có | L33: Đúng | M33: =RIGHT(IF(F33="—","",F33)&IF(L33="Đúng","Đ","S"),'Quy tac'!$B$7) -> SSĐ | N33: =(LEN(M33)-LEN(SUBSTITUTE(M33,"S",""))+1)/(LEN(M33)+2) -> 0.6 | O33: =IF(H33="—",IF(L33="Đúng",INDEX('Quy tac'!$B$17:$B$22,2),INDEX('Quy tac'!$B$17:$B$22,1)),IF(L33="Sai",INDEX('Quy tac'!$B$17:$B$22,1),IF(I33>=H33,INDEX('Quy tac'!$B$17:$B$22,MIN(MATCH(H33,'Quy tac'!$B$17:$B$22,0)+1,6)),H33))) -> 3 | P33: =B33+O33 -> 7 | Q33: =IF(H33="—",IF(L33="Đúng","Lần đầu đúng → 3 ngày","Lần đầu sai → 1 ngày"),IF(L33="Sai","Sai → về 1 ngày",IF(I33>=H33,"Đúng, đến hạn → lên 1 bậc","Đúng nhưng ôn sớm → giữ bậc"))) -> Đúng, đến hạn → lên 1 bậc
A34: 4 | B34: 4 | C34: 3 | D34: Q17 | E34: Yếu | F34: SS | G34: =IF(F34="—","—",(LEN(F34)-LEN(SUBSTITUTE(F34,"S",""))+1)/(LEN(F34)+2)) -> 0.75 | H34: 1 | I34: 1 | J34: =IF(H34="—","—",'Quy tac'!$B$5^(I34/H34)) -> 0.9 | K34: =IF(H34="—","Câu mới",IF(I34>=H34,"Có","Chưa")) -> Có | L34: Đúng | M34: =RIGHT(IF(F34="—","",F34)&IF(L34="Đúng","Đ","S"),'Quy tac'!$B$7) -> SSĐ | N34: =(LEN(M34)-LEN(SUBSTITUTE(M34,"S",""))+1)/(LEN(M34)+2) -> 0.6 | O34: =IF(H34="—",IF(L34="Đúng",INDEX('Quy tac'!$B$17:$B$22,2),INDEX('Quy tac'!$B$17:$B$22,1)),IF(L34="Sai",INDEX('Quy tac'!$B$17:$B$22,1),IF(I34>=H34,INDEX('Quy tac'!$B$17:$B$22,MIN(MATCH(H34,'Quy tac'!$B$17:$B$22,0)+1,6)),H34))) -> 3 | P34: =B34+O34 -> 7 | Q34: =IF(H34="—",IF(L34="Đúng","Lần đầu đúng → 3 ngày","Lần đầu sai → 1 ngày"),IF(L34="Sai","Sai → về 1 ngày",IF(I34>=H34,"Đúng, đến hạn → lên 1 bậc","Đúng nhưng ôn sớm → giữ bậc"))) -> Đúng, đến hạn → lên 1 bậc
A35: 4 | B35: 4 | C35: 4 | D35: Q21 | E35: Yếu | F35: S | G35: =IF(F35="—","—",(LEN(F35)-LEN(SUBSTITUTE(F35,"S",""))+1)/(LEN(F35)+2)) -> 0.66666667 | H35: 1 | I35: 1 | J35: =IF(H35="—","—",'Quy tac'!$B$5^(I35/H35)) -> 0.9 | K35: =IF(H35="—","Câu mới",IF(I35>=H35,"Có","Chưa")) -> Có | L35: Đúng | M35: =RIGHT(IF(F35="—","",F35)&IF(L35="Đúng","Đ","S"),'Quy tac'!$B$7) -> SĐ | N35: =(LEN(M35)-LEN(SUBSTITUTE(M35,"S",""))+1)/(LEN(M35)+2) -> 0.5 | O35: =IF(H35="—",IF(L35="Đúng",INDEX('Quy tac'!$B$17:$B$22,2),INDEX('Quy tac'!$B$17:$B$22,1)),IF(L35="Sai",INDEX('Quy tac'!$B$17:$B$22,1),IF(I35>=H35,INDEX('Quy tac'!$B$17:$B$22,MIN(MATCH(H35,'Quy tac'!$B$17:$B$22,0)+1,6)),H35))) -> 3 | P35: =B35+O35 -> 7 | Q35: =IF(H35="—",IF(L35="Đúng","Lần đầu đúng → 3 ngày","Lần đầu sai → 1 ngày"),IF(L35="Sai","Sai → về 1 ngày",IF(I35>=H35,"Đúng, đến hạn → lên 1 bậc","Đúng nhưng ôn sớm → giữ bậc"))) -> Đúng, đến hạn → lên 1 bậc
A36: 4 | B36: 4 | C36: 5 | D36: Q05 | E36: Sắp quên | F36: SĐS | G36: =IF(F36="—","—",(LEN(F36)-LEN(SUBSTITUTE(F36,"S",""))+1)/(LEN(F36)+2)) -> 0.6 | H36: 1 | I36: 1 | J36: =IF(H36="—","—",'Quy tac'!$B$5^(I36/H36)) -> 0.9 | K36: =IF(H36="—","Câu mới",IF(I36>=H36,"Có","Chưa")) -> Có | L36: Đúng | M36: =RIGHT(IF(F36="—","",F36)&IF(L36="Đúng","Đ","S"),'Quy tac'!$B$7) -> SĐSĐ | N36: =(LEN(M36)-LEN(SUBSTITUTE(M36,"S",""))+1)/(LEN(M36)+2) -> 0.5 | O36: =IF(H36="—",IF(L36="Đúng",INDEX('Quy tac'!$B$17:$B$22,2),INDEX('Quy tac'!$B$17:$B$22,1)),IF(L36="Sai",INDEX('Quy tac'!$B$17:$B$22,1),IF(I36>=H36,INDEX('Quy tac'!$B$17:$B$22,MIN(MATCH(H36,'Quy tac'!$B$17:$B$22,0)+1,6)),H36))) -> 3 | P36: =B36+O36 -> 7 | Q36: =IF(H36="—",IF(L36="Đúng","Lần đầu đúng → 3 ngày","Lần đầu sai → 1 ngày"),IF(L36="Sai","Sai → về 1 ngày",IF(I36>=H36,"Đúng, đến hạn → lên 1 bậc","Đúng nhưng ôn sớm → giữ bậc"))) -> Đúng, đến hạn → lên 1 bậc
A37: 4 | B37: 4 | C37: 6 | D37: Q01 | E37: Sắp quên | F37: Đ | G37: =IF(F37="—","—",(LEN(F37)-LEN(SUBSTITUTE(F37,"S",""))+1)/(LEN(F37)+2)) -> 0.33333333 | H37: 3 | I37: 3 | J37: =IF(H37="—","—",'Quy tac'!$B$5^(I37/H37)) -> 0.9 | K37: =IF(H37="—","Câu mới",IF(I37>=H37,"Có","Chưa")) -> Có | L37: Sai | M37: =RIGHT(IF(F37="—","",F37)&IF(L37="Đúng","Đ","S"),'Quy tac'!$B$7) -> ĐS | N37: =(LEN(M37)-LEN(SUBSTITUTE(M37,"S",""))+1)/(LEN(M37)+2) -> 0.5 | O37: =IF(H37="—",IF(L37="Đúng",INDEX('Quy tac'!$B$17:$B$22,2),INDEX('Quy tac'!$B$17:$B$22,1)),IF(L37="Sai",INDEX('Quy tac'!$B$17:$B$22,1),IF(I37>=H37,INDEX('Quy tac'!$B$17:$B$22,MIN(MATCH(H37,'Quy tac'!$B$17:$B$22,0)+1,6)),H37))) -> 1 | P37: =B37+O37 -> 5 | Q37: =IF(H37="—",IF(L37="Đúng","Lần đầu đúng → 3 ngày","Lần đầu sai → 1 ngày"),IF(L37="Sai","Sai → về 1 ngày",IF(I37>=H37,"Đúng, đến hạn → lên 1 bậc","Đúng nhưng ôn sớm → giữ bậc"))) -> Sai → về 1 ngày
A38: 4 | B38: 4 | C38: 7 | D38: Q02 | E38: Sắp quên | F38: Đ | G38: =IF(F38="—","—",(LEN(F38)-LEN(SUBSTITUTE(F38,"S",""))+1)/(LEN(F38)+2)) -> 0.33333333 | H38: 3 | I38: 3 | J38: =IF(H38="—","—",'Quy tac'!$B$5^(I38/H38)) -> 0.9 | K38: =IF(H38="—","Câu mới",IF(I38>=H38,"Có","Chưa")) -> Có | L38: Đúng | M38: =RIGHT(IF(F38="—","",F38)&IF(L38="Đúng","Đ","S"),'Quy tac'!$B$7) -> ĐĐ | N38: =(LEN(M38)-LEN(SUBSTITUTE(M38,"S",""))+1)/(LEN(M38)+2) -> 0.25 | O38: =IF(H38="—",IF(L38="Đúng",INDEX('Quy tac'!$B$17:$B$22,2),INDEX('Quy tac'!$B$17:$B$22,1)),IF(L38="Sai",INDEX('Quy tac'!$B$17:$B$22,1),IF(I38>=H38,INDEX('Quy tac'!$B$17:$B$22,MIN(MATCH(H38,'Quy tac'!$B$17:$B$22,0)+1,6)),H38))) -> 7 | P38: =B38+O38 -> 11 | Q38: =IF(H38="—",IF(L38="Đúng","Lần đầu đúng → 3 ngày","Lần đầu sai → 1 ngày"),IF(L38="Sai","Sai → về 1 ngày",IF(I38>=H38,"Đúng, đến hạn → lên 1 bậc","Đúng nhưng ôn sớm → giữ bậc"))) -> Đúng, đến hạn → lên 1 bậc
A39: 4 | B39: 4 | C39: 8 | D39: Q22 | E39: Mới | F39: — | G39: =IF(F39="—","—",(LEN(F39)-LEN(SUBSTITUTE(F39,"S",""))+1)/(LEN(F39)+2)) -> — | H39: — | I39: — | J39: =IF(H39="—","—",'Quy tac'!$B$5^(I39/H39)) -> — | K39: =IF(H39="—","Câu mới",IF(I39>=H39,"Có","Chưa")) -> Câu mới | L39: Đúng | M39: =RIGHT(IF(F39="—","",F39)&IF(L39="Đúng","Đ","S"),'Quy tac'!$B$7) -> Đ | N39: =(LEN(M39)-LEN(SUBSTITUTE(M39,"S",""))+1)/(LEN(M39)+2) -> 0.33333333 | O39: =IF(H39="—",IF(L39="Đúng",INDEX('Quy tac'!$B$17:$B$22,2),INDEX('Quy tac'!$B$17:$B$22,1)),IF(L39="Sai",INDEX('Quy tac'!$B$17:$B$22,1),IF(I39>=H39,INDEX('Quy tac'!$B$17:$B$22,MIN(MATCH(H39,'Quy tac'!$B$17:$B$22,0)+1,6)),H39))) -> 3 | P39: =B39+O39 -> 7 | Q39: =IF(H39="—",IF(L39="Đúng","Lần đầu đúng → 3 ngày","Lần đầu sai → 1 ngày"),IF(L39="Sai","Sai → về 1 ngày",IF(I39>=H39,"Đúng, đến hạn → lên 1 bậc","Đúng nhưng ôn sớm → giữ bậc"))) -> Lần đầu đúng → 3 ngày
A40: 4 | B40: 4 | C40: 9 | D40: Q23 | E40: Mới | F40: — | G40: =IF(F40="—","—",(LEN(F40)-LEN(SUBSTITUTE(F40,"S",""))+1)/(LEN(F40)+2)) -> — | H40: — | I40: — | J40: =IF(H40="—","—",'Quy tac'!$B$5^(I40/H40)) -> — | K40: =IF(H40="—","Câu mới",IF(I40>=H40,"Có","Chưa")) -> Câu mới | L40: Sai | M40: =RIGHT(IF(F40="—","",F40)&IF(L40="Đúng","Đ","S"),'Quy tac'!$B$7) -> S | N40: =(LEN(M40)-LEN(SUBSTITUTE(M40,"S",""))+1)/(LEN(M40)+2) -> 0.66666667 | O40: =IF(H40="—",IF(L40="Đúng",INDEX('Quy tac'!$B$17:$B$22,2),INDEX('Quy tac'!$B$17:$B$22,1)),IF(L40="Sai",INDEX('Quy tac'!$B$17:$B$22,1),IF(I40>=H40,INDEX('Quy tac'!$B$17:$B$22,MIN(MATCH(H40,'Quy tac'!$B$17:$B$22,0)+1,6)),H40))) -> 1 | P40: =B40+O40 -> 5 | Q40: =IF(H40="—",IF(L40="Đúng","Lần đầu đúng → 3 ngày","Lần đầu sai → 1 ngày"),IF(L40="Sai","Sai → về 1 ngày",IF(I40>=H40,"Đúng, đến hạn → lên 1 bậc","Đúng nhưng ôn sớm → giữ bậc"))) -> Lần đầu sai → 1 ngày
...

Sheet Tong quan phien
A1: Phiên | B1: Ngày | C1: Câu đã làm trước phiên | D1: Câu chưa làm | E1: Đang nghỉ (bị loại) | F1: Cỡ nhóm Yếu | G1: Cỡ nhóm Sắp quên | H1: Chọn: Yếu | I1: Chọn: Sắp quên | J1: Chọn: Mới | K1: Đúng / 10 | L1: Đúng ở câu mới | M1: Đúng ở câu ôn
A2: 1 | B2: 1 | C2: 0 | D2: 50 | E2: 0 | F2: 0 | G2: 0 | H2: =COUNTIFS('Nhat ky'!$A$2:$A$101,A2,'Nhat ky'!$E$2:$E$101,"Yếu") -> 0 | I2: =COUNTIFS('Nhat ky'!$A$2:$A$101,A2,'Nhat ky'!$E$2:$E$101,"Sắp quên") -> 0 | J2: =COUNTIFS('Nhat ky'!$A$2:$A$101,A2,'Nhat ky'!$E$2:$E$101,"Mới") -> 10 | K2: =COUNTIFS('Nhat ky'!$A$2:$A$101,A2,'Nhat ky'!$L$2:$L$101,"Đúng") -> 7 | L2: =COUNTIFS('Nhat ky'!$A$2:$A$101,A2,'Nhat ky'!$E$2:$E$101,"Mới",'Nhat ky'!$L$2:$L$101,"Đúng")&"/"&J2 -> 7/10 | M2: =(K2-COUNTIFS('Nhat ky'!$A$2:$A$101,A2,'Nhat ky'!$E$2:$E$101,"Mới",'Nhat ky'!$L$2:$L$101,"Đúng"))&"/"&(10-J2) -> 0/0
A3: 2 | B3: 2 | C3: 10 | D3: 40 | E3: 0 | F3: 3 | G3: 3 | H3: =COUNTIFS('Nhat ky'!$A$2:$A$101,A3,'Nhat ky'!$E$2:$E$101,"Yếu") -> 3 | I3: =COUNTIFS('Nhat ky'!$A$2:$A$101,A3,'Nhat ky'!$E$2:$E$101,"Sắp quên") -> 0 | J3: =COUNTIFS('Nhat ky'!$A$2:$A$101,A3,'Nhat ky'!$E$2:$E$101,"Mới") -> 7 | K3: =COUNTIFS('Nhat ky'!$A$2:$A$101,A3,'Nhat ky'!$L$2:$L$101,"Đúng") -> 6 | L3: =COUNTIFS('Nhat ky'!$A$2:$A$101,A3,'Nhat ky'!$E$2:$E$101,"Mới",'Nhat ky'!$L$2:$L$101,"Đúng")&"/"&J3 -> 4/7 | M3: =(K3-COUNTIFS('Nhat ky'!$A$2:$A$101,A3,'Nhat ky'!$E$2:$E$101,"Mới",'Nhat ky'!$L$2:$L$101,"Đúng"))&"/"&(10-J3) -> 2/3
A4: 3 | B4: 3 | C4: 17 | D4: 33 | E4: 0 | F4: 6 | G4: 4 | H4: =COUNTIFS('Nhat ky'!$A$2:$A$101,A4,'Nhat ky'!$E$2:$E$101,"Yếu") -> 6 | I4: =COUNTIFS('Nhat ky'!$A$2:$A$101,A4,'Nhat ky'!$E$2:$E$101,"Sắp quên") -> 0 | J4: =COUNTIFS('Nhat ky'!$A$2:$A$101,A4,'Nhat ky'!$E$2:$E$101,"Mới") -> 4 | K4: =COUNTIFS('Nhat ky'!$A$2:$A$101,A4,'Nhat ky'!$L$2:$L$101,"Đúng") -> 5 | L4: =COUNTIFS('Nhat ky'!$A$2:$A$101,A4,'Nhat ky'!$E$2:$E$101,"Mới",'Nhat ky'!$L$2:$L$101,"Đúng")&"/"&J4 -> 3/4 | M4: =(K4-COUNTIFS('Nhat ky'!$A$2:$A$101,A4,'Nhat ky'!$E$2:$E$101,"Mới",'Nhat ky'!$L$2:$L$101,"Đúng"))&"/"&(10-J4) -> 2/6
A5: 4 | B5: 4 | C5: 21 | D5: 29 | E5: 0 | F5: 6 | G5: 12 | H5: =COUNTIFS('Nhat ky'!$A$2:$A$101,A5,'Nhat ky'!$E$2:$E$101,"Yếu") -> 4 | I5: =COUNTIFS('Nhat ky'!$A$2:$A$101,A5,'Nhat ky'!$E$2:$E$101,"Sắp quên") -> 3 | J5: =COUNTIFS('Nhat ky'!$A$2:$A$101,A5,'Nhat ky'!$E$2:$E$101,"Mới") -> 3 | K5: =COUNTIFS('Nhat ky'!$A$2:$A$101,A5,'Nhat ky'!$L$2:$L$101,"Đúng") -> 7 | L5: =COUNTIFS('Nhat ky'!$A$2:$A$101,A5,'Nhat ky'!$E$2:$E$101,"Mới",'Nhat ky'!$L$2:$L$101,"Đúng")&"/"&J5 -> 1/3 | M5: =(K5-COUNTIFS('Nhat ky'!$A$2:$A$101,A5,'Nhat ky'!$E$2:$E$101,"Mới",'Nhat ky'!$L$2:$L$101,"Đúng"))&"/"&(10-J5) -> 6/7
A6: 5 | B6: 5 | C6: 24 | D6: 26 | E6: 0 | F6: 9 | G6: 12 | H6: =COUNTIFS('Nhat ky'!$A$2:$A$101,A6,'Nhat ky'!$E$2:$E$101,"Yếu") -> 4 | I6: =COUNTIFS('Nhat ky'!$A$2:$A$101,A6,'Nhat ky'!$E$2:$E$101,"Sắp quên") -> 3 | J6: =COUNTIFS('Nhat ky'!$A$2:$A$101,A6,'Nhat ky'!$E$2:$E$101,"Mới") -> 3 | K6: =COUNTIFS('Nhat ky'!$A$2:$A$101,A6,'Nhat ky'!$L$2:$L$101,"Đúng") -> 6 | L6: =COUNTIFS('Nhat ky'!$A$2:$A$101,A6,'Nhat ky'!$E$2:$E$101,"Mới",'Nhat ky'!$L$2:$L$101,"Đúng")&"/"&J6 -> 2/3 | M6: =(K6-COUNTIFS('Nhat ky'!$A$2:$A$101,A6,'Nhat ky'!$E$2:$E$101,"Mới",'Nhat ky'!$L$2:$L$101,"Đúng"))&"/"&(10-J6) -> 4/7
A7: 6 | B7: 5.5 | C7: 27 | D7: 23 | E7: 10 | F7: 5 | G7: 7 | H7: =COUNTIFS('Nhat ky'!$A$2:$A$101,A7,'Nhat ky'!$E$2:$E$101,"Yếu") -> 4 | I7: =COUNTIFS('Nhat ky'!$A$2:$A$101,A7,'Nhat ky'!$E$2:$E$101,"Sắp quên") -> 3 | J7: =COUNTIFS('Nhat ky'!$A$2:$A$101,A7,'Nhat ky'!$E$2:$E$101,"Mới") -> 3 | K7: =COUNTIFS('Nhat ky'!$A$2:$A$101,A7,'Nhat ky'!$L$2:$L$101,"Đúng") -> 6 | L7: =COUNTIFS('Nhat ky'!$A$2:$A$101,A7,'Nhat ky'!$E$2:$E$101,"Mới",'Nhat ky'!$L$2:$L$101,"Đúng")&"/"&J7 -> 3/3 | M7: =(K7-COUNTIFS('Nhat ky'!$A$2:$A$101,A7,'Nhat ky'!$E$2:$E$101,"Mới",'Nhat ky'!$L$2:$L$101,"Đúng"))&"/"&(10-J7) -> 3/7
A8: 7 | B8: 8 | C8: 30 | D8: 20 | E8: 0 | F8: 14 | G8: 23 | H8: =COUNTIFS('Nhat ky'!$A$2:$A$101,A8,'Nhat ky'!$E$2:$E$101,"Yếu") -> 4 | I8: =COUNTIFS('Nhat ky'!$A$2:$A$101,A8,'Nhat ky'!$E$2:$E$101,"Sắp quên") -> 3 | J8: =COUNTIFS('Nhat ky'!$A$2:$A$101,A8,'Nhat ky'!$E$2:$E$101,"Mới") -> 3 | K8: =COUNTIFS('Nhat ky'!$A$2:$A$101,A8,'Nhat ky'!$L$2:$L$101,"Đúng") -> 9 | L8: =COUNTIFS('Nhat ky'!$A$2:$A$101,A8,'Nhat ky'!$E$2:$E$101,"Mới",'Nhat ky'!$L$2:$L$101,"Đúng")&"/"&J8 -> 2/3 | M8: =(K8-COUNTIFS('Nhat ky'!$A$2:$A$101,A8,'Nhat ky'!$E$2:$E$101,"Mới",'Nhat ky'!$L$2:$L$101,"Đúng"))&"/"&(10-J8) -> 7/7
A9: 8 | B9: 10 | C9: 33 | D9: 17 | E9: 0 | F9: 11 | G9: 22 | H9: =COUNTIFS('Nhat ky'!$A$2:$A$101,A9,'Nhat ky'!$E$2:$E$101,"Yếu") -> 4 | I9: =COUNTIFS('Nhat ky'!$A$2:$A$101,A9,'Nhat ky'!$E$2:$E$101,"Sắp quên") -> 3 | J9: =COUNTIFS('Nhat ky'!$A$2:$A$101,A9,'Nhat ky'!$E$2:$E$101,"Mới") -> 3 | K9: =COUNTIFS('Nhat ky'!$A$2:$A$101,A9,'Nhat ky'!$L$2:$L$101,"Đúng") -> 5 | L9: =COUNTIFS('Nhat ky'!$A$2:$A$101,A9,'Nhat ky'!$E$2:$E$101,"Mới",'Nhat ky'!$L$2:$L$101,"Đúng")&"/"&J9 -> 2/3 | M9: =(K9-COUNTIFS('Nhat ky'!$A$2:$A$101,A9,'Nhat ky'!$E$2:$E$101,"Mới",'Nhat ky'!$L$2:$L$101,"Đúng"))&"/"&(10-J9) -> 3/7
A10: 9 | B10: 13 | C10: 36 | D10: 14 | E10: 0 | F10: 13 | G10: 34 | H10: =COUNTIFS('Nhat ky'!$A$2:$A$101,A10,'Nhat ky'!$E$2:$E$101,"Yếu") -> 4 | I10: =COUNTIFS('Nhat ky'!$A$2:$A$101,A10,'Nhat ky'!$E$2:$E$101,"Sắp quên") -> 3 | J10: =COUNTIFS('Nhat ky'!$A$2:$A$101,A10,'Nhat ky'!$E$2:$E$101,"Mới") -> 3 | K10: =COUNTIFS('Nhat ky'!$A$2:$A$101,A10,'Nhat ky'!$L$2:$L$101,"Đúng") -> 4 | L10: =COUNTIFS('Nhat ky'!$A$2:$A$101,A10,'Nhat ky'!$E$2:$E$101,"Mới",'Nhat ky'!$L$2:$L$101,"Đúng")&"/"&J10 -> 1/3 | M10: =(K10-COUNTIFS('Nhat ky'!$A$2:$A$101,A10,'Nhat ky'!$E$2:$E$101,"Mới",'Nhat ky'!$L$2:$L$101,"Đúng"))&"/"&(10-J10) -> 3/7
A11: 10 | B11: 17 | C11: 39 | D11: 11 | E11: 0 | F11: 15 | G11: 37 | H11: =COUNTIFS('Nhat ky'!$A$2:$A$101,A11,'Nhat ky'!$E$2:$E$101,"Yếu") -> 4 | I11: =COUNTIFS('Nhat ky'!$A$2:$A$101,A11,'Nhat ky'!$E$2:$E$101,"Sắp quên") -> 3 | J11: =COUNTIFS('Nhat ky'!$A$2:$A$101,A11,'Nhat ky'!$E$2:$E$101,"Mới") -> 3 | K11: =COUNTIFS('Nhat ky'!$A$2:$A$101,A11,'Nhat ky'!$L$2:$L$101,"Đúng") -> 5 | L11: =COUNTIFS('Nhat ky'!$A$2:$A$101,A11,'Nhat ky'!$E$2:$E$101,"Mới",'Nhat ky'!$L$2:$L$101,"Đúng")&"/"&J11 -> 2/3 | M11: =(K11-COUNTIFS('Nhat ky'!$A$2:$A$101,A11,'Nhat ky'!$E$2:$E$101,"Mới",'Nhat ky'!$L$2:$L$101,"Đúng"))&"/"&(10-J11) -> 3/7
A13: Cột C–G (xanh dương) lấy từ mô phỏng tại thời điểm dựng phiên; cột H–M tính từ sheet 'Nhat ky'.
A14: Phiên 6 diễn ra tối cùng ngày 5 (ngày 5,5): 10 câu của phiên 5 mới làm 12 giờ trước nên bị loại vì chưa đủ 20 giờ nghỉ.

Sheet Trang thai ngay 17
A1: Trạng thái 50 câu tại ngày 17 (ngay sau phiên 10)
A2: Ngày xét | B2: 17
A4: Mã câu | B4: Số lần đã làm | C4: Lịch sử 5 lần (cũ→mới) | D4: Độ yếu | E4: S (ngày) | F4: Lần làm cuối (ngày) | G4: t (ngày) | H4: R hôm nay | I4: Hạn ôn | J4: Thuộc nhóm | L4: Thống kê
A5: Q01 | B5: 4 | C5: ĐSSĐ | D5: =(LEN(C5)-LEN(SUBSTITUTE(C5,"S",""))+1)/(LEN(C5)+2) -> 0.5 | E5: 3 | F5: 8 | G5: =$B$2-F5 -> 9 | H5: ='Quy tac'!$B$5^(G5/E5) -> 0.729 | I5: =F5+E5 -> 11 | J5: =IF(AND(D5>='Quy tac'!$B$6,G5>=E5),"Yếu + sắp quên",IF(D5>='Quy tac'!$B$6,"Yếu",IF(G5>=E5,"Sắp quên","Ổn định"))) -> Yếu + sắp quên | L5: Chưa làm | M5: =COUNTIF($J$5:$J$54,L5) -> 8
A6: Q02 | B6: 2 | C6: ĐĐ | D6: =(LEN(C6)-LEN(SUBSTITUTE(C6,"S",""))+1)/(LEN(C6)+2) -> 0.25 | E6: 7 | F6: 4 | G6: =$B$2-F6 -> 13 | H6: ='Quy tac'!$B$5^(G6/E6) -> 0.82228393 | I6: =F6+E6 -> 11 | J6: =IF(AND(D6>='Quy tac'!$B$6,G6>=E6),"Yếu + sắp quên",IF(D6>='Quy tac'!$B$6,"Yếu",IF(G6>=E6,"Sắp quên","Ổn định"))) -> Sắp quên | L6: Yếu | M6: =COUNTIF($J$5:$J$54,L6) -> 7
A7: Q03 | B7: 6 | C7: SSĐĐĐ | D7: =(LEN(C7)-LEN(SUBSTITUTE(C7,"S",""))+1)/(LEN(C7)+2) -> 0.42857143 | E7: 7 | F7: 8 | G7: =$B$2-F7 -> 9 | H7: ='Quy tac'!$B$5^(G7/E7) -> 0.87331102 | I7: =F7+E7 -> 15 | J7: =IF(AND(D7>='Quy tac'!$B$6,G7>=E7),"Yếu + sắp quên",IF(D7>='Quy tac'!$B$6,"Yếu",IF(G7>=E7,"Sắp quên","Ổn định"))) -> Sắp quên | L7: Sắp quên | M7: =COUNTIF($J$5:$J$54,L7) -> 20
A8: Q04 | B8: 3 | C8: ĐSĐ | D8: =(LEN(C8)-LEN(SUBSTITUTE(C8,"S",""))+1)/(LEN(C8)+2) -> 0.4 | E8: 3 | F8: 8 | G8: =$B$2-F8 -> 9 | H8: ='Quy tac'!$B$5^(G8/E8) -> 0.729 | I8: =F8+E8 -> 11 | J8: =IF(AND(D8>='Quy tac'!$B$6,G8>=E8),"Yếu + sắp quên",IF(D8>='Quy tac'!$B$6,"Yếu",IF(G8>=E8,"Sắp quên","Ổn định"))) -> Sắp quên | L8: Yếu + sắp quên | M8: =COUNTIF($J$5:$J$54,L8) -> 10
A9: Q05 | B9: 5 | C9: SĐSĐĐ | D9: =(LEN(C9)-LEN(SUBSTITUTE(C9,"S",""))+1)/(LEN(C9)+2) -> 0.42857143 | E9: 3 | F9: 5.5 | G9: =$B$2-F9 -> 11.5 | H9: ='Quy tac'!$B$5^(G9/E9) -> 0.66772292 | I9: =F9+E9 -> 8.5 | J9: =IF(AND(D9>='Quy tac'!$B$6,G9>=E9),"Yếu + sắp quên",IF(D9>='Quy tac'!$B$6,"Yếu",IF(G9>=E9,"Sắp quên","Ổn định"))) -> Sắp quên | L9: Ổn định | M9: =COUNTIF($J$5:$J$54,L9) -> 5
A10: Q06 | B10: 3 | C10: ĐSĐ | D10: =(LEN(C10)-LEN(SUBSTITUTE(C10,"S",""))+1)/(LEN(C10)+2) -> 0.4 | E10: 3 | F10: 8 | G10: =$B$2-F10 -> 9 | H10: ='Quy tac'!$B$5^(G10/E10) -> 0.729 | I10: =F10+E10 -> 11 | J10: =IF(AND(D10>='Quy tac'!$B$6,G10>=E10),"Yếu + sắp quên",IF(D10>='Quy tac'!$B$6,"Yếu",IF(G10>=E10,"Sắp quên","Ổn định"))) -> Sắp quên
A11: Q07 | B11: 3 | C11: ĐSĐ | D11: =(LEN(C11)-LEN(SUBSTITUTE(C11,"S",""))+1)/(LEN(C11)+2) -> 0.4 | E11: 3 | F11: 8 | G11: =$B$2-F11 -> 9 | H11: ='Quy tac'!$B$5^(G11/E11) -> 0.729 | I11: =F11+E11 -> 11 | J11: =IF(AND(D11>='Quy tac'!$B$6,G11>=E11),"Yếu + sắp quên",IF(D11>='Quy tac'!$B$6,"Yếu",IF(G11>=E11,"Sắp quên","Ổn định"))) -> Sắp quên
A12: Q08 | B12: 2 | C12: ĐĐ | D12: =(LEN(C12)-LEN(SUBSTITUTE(C12,"S",""))+1)/(LEN(C12)+2) -> 0.25 | E12: 7 | F12: 5.5 | G12: =$B$2-F12 -> 11.5 | H12: ='Quy tac'!$B$5^(G12/E12) -> 0.84106 | I12: =F12+E12 -> 12.5 | J12: =IF(AND(D12>='Quy tac'!$B$6,G12>=E12),"Yếu + sắp quên",IF(D12>='Quy tac'!$B$6,"Yếu",IF(G12>=E12,"Sắp quên","Ổn định"))) -> Sắp quên
A13: Q09 | B13: 5 | C13: ĐSSSĐ | D13: =(LEN(C13)-LEN(SUBSTITUTE(C13,"S",""))+1)/(LEN(C13)+2) -> 0.57142857 | E13: 3 | F13: 17 | G13: =$B$2-F13 -> 0 | H13: ='Quy tac'!$B$5^(G13/E13) -> 1 | I13: =F13+E13 -> 20 | J13: =IF(AND(D13>='Quy tac'!$B$6,G13>=E13),"Yếu + sắp quên",IF(D13>='Quy tac'!$B$6,"Yếu",IF(G13>=E13,"Sắp quên","Ổn định"))) -> Yếu
A14: Q10 | B14: 4 | C14: SĐĐS | D14: =(LEN(C14)-LEN(SUBSTITUTE(C14,"S",""))+1)/(LEN(C14)+2) -> 0.5 | E14: 1 | F14: 13 | G14: =$B$2-F14 -> 4 | H14: ='Quy tac'!$B$5^(G14/E14) -> 0.6561 | I14: =F14+E14 -> 14 | J14: =IF(AND(D14>='Quy tac'!$B$6,G14>=E14),"Yếu + sắp quên",IF(D14>='Quy tac'!$B$6,"Yếu",IF(G14>=E14,"Sắp quên","Ổn định"))) -> Yếu + sắp quên
A15: Q11 | B15: 3 | C15: ĐSĐ | D15: =(LEN(C15)-LEN(SUBSTITUTE(C15,"S",""))+1)/(LEN(C15)+2) -> 0.4 | E15: 3 | F15: 10 | G15: =$B$2-F15 -> 7 | H15: ='Quy tac'!$B$5^(G15/E15) -> 0.7820464 | I15: =F15+E15 -> 13 | J15: =IF(AND(D15>='Quy tac'!$B$6,G15>=E15),"Yếu + sắp quên",IF(D15>='Quy tac'!$B$6,"Yếu",IF(G15>=E15,"Sắp quên","Ổn định"))) -> Sắp quên
A16: Q12 | B16: 3 | C16: ĐSS | D16: =(LEN(C16)-LEN(SUBSTITUTE(C16,"S",""))+1)/(LEN(C16)+2) -> 0.6 | E16: 1 | F16: 13 | G16: =$B$2-F16 -> 4 | H16: ='Quy tac'!$B$5^(G16/E16) -> 0.6561 | I16: =F16+E16 -> 14 | J16: =IF(AND(D16>='Quy tac'!$B$6,G16>=E16),"Yếu + sắp quên",IF(D16>='Quy tac'!$B$6,"Yếu",IF(G16>=E16,"Sắp quên","Ổn định"))) -> Yếu + sắp quên
A17: Q13 | B17: 3 | C17: ĐSĐ | D17: =(LEN(C17)-LEN(SUBSTITUTE(C17,"S",""))+1)/(LEN(C17)+2) -> 0.4 | E17: 3 | F17: 13 | G17: =$B$2-F17 -> 4 | H17: ='Quy tac'!$B$5^(G17/E17) -> 0.86894045 | I17: =F17+E17 -> 16 | J17: =IF(AND(D17>='Quy tac'!$B$6,G17>=E17),"Yếu + sắp quên",IF(D17>='Quy tac'!$B$6,"Yếu",IF(G17>=E17,"Sắp quên","Ổn định"))) -> Sắp quên
A18: Q14 | B18: 4 | C18: SSĐĐ | D18: =(LEN(C18)-LEN(SUBSTITUTE(C18,"S",""))+1)/(LEN(C18)+2) -> 0.5 | E18: 3 | F18: 5 | G18: =$B$2-F18 -> 12 | H18: ='Quy tac'!$B$5^(G18/E18) -> 0.6561 | I18: =F18+E18 -> 8 | J18: =IF(AND(D18>='Quy tac'!$B$6,G18>=E18),"Yếu + sắp quên",IF(D18>='Quy tac'!$B$6,"Yếu",IF(G18>=E18,"Sắp quên","Ổn định"))) -> Yếu + sắp quên
A19: Q15 | B19: 4 | C19: SĐSĐ | D19: =(LEN(C19)-LEN(SUBSTITUTE(C19,"S",""))+1)/(LEN(C19)+2) -> 0.5 | E19: 3 | F19: 8 | G19: =$B$2-F19 -> 9 | H19: ='Quy tac'!$B$5^(G19/E19) -> 0.729 | I19: =F19+E19 -> 11 | J19: =IF(AND(D19>='Quy tac'!$B$6,G19>=E19),"Yếu + sắp quên",IF(D19>='Quy tac'!$B$6,"Yếu",IF(G19>=E19,"Sắp quên","Ổn định"))) -> Yếu + sắp quên
A20: Q16 | B20: 3 | C20: ĐSS | D20: =(LEN(C20)-LEN(SUBSTITUTE(C20,"S",""))+1)/(LEN(C20)+2) -> 0.6 | E20: 1 | F20: 17 | G20: =$B$2-F20 -> 0 | H20: ='Quy tac'!$B$5^(G20/E20) -> 1 | I20: =F20+E20 -> 18 | J20: =IF(AND(D20>='Quy tac'!$B$6,G20>=E20),"Yếu + sắp quên",IF(D20>='Quy tac'!$B$6,"Yếu",IF(G20>=E20,"Sắp quên","Ổn định"))) -> Yếu
A21: Q17 | B21: 4 | C21: SSĐĐ | D21: =(LEN(C21)-LEN(SUBSTITUTE(C21,"S",""))+1)/(LEN(C21)+2) -> 0.5 | E21: 3 | F21: 5.5 | G21: =$B$2-F21 -> 11.5 | H21: ='Quy tac'!$B$5^(G21/E21) -> 0.66772292 | I21: =F21+E21 -> 8.5 | J21: =IF(AND(D21>='Quy tac'!$B$6,G21>=E21),"Yếu + sắp quên",IF(D21>='Quy tac'!$B$6,"Yếu",IF(G21>=E21,"Sắp quên","Ổn định"))) -> Yếu + sắp quên
... A46: Q42 | B46: 1 | C46: Đ | D46: =(LEN(C46)-LEN(SUBSTITUTE(C46,"S",""))+1)/(LEN(C46)+2) -> 0.33333333 | E46: 3 | F46: 17 | G46: =$B$2-F46 -> 0 | H46: ='Quy tac'!$B$5^(G46/E46) -> 1 | I46: =F46+E46 -> 20 | J46: =IF(AND(D46>='Quy tac'!$B$6,G46>=E46),"Yếu + sắp quên",IF(D46>='Quy tac'!$B$6,"Yếu",IF(G46>=E46,"Sắp quên","Ổn định"))) -> Ổn định
A47: Q43 | B47: 0 | C47: — | D47: — | E47: — | F47: — | G47: — | H47: — | I47: — | J47: Chưa làm
A48: Q44 | B48: 0 | C48: — | D48: — | E48: — | F48: — | G48: — | H48: — | I48: — | J48: Chưa làm
A49: Q45 | B49: 0 | C49: — | D49: — | E49: — | F49: — | G49: — | H49: — | I49: — | J49: Chưa làm
A50: Q46 | B50: 0 | C50: — | D50: — | E50: — | F50: — | G50: — | H50: — | I50: — | J50: Chưa làm
A51: Q47 | B51: 0 | C51: — | D51: — | E51: — | F51: — | G51: — | H51: — | I51: — | J51: Chưa làm
A52: Q48 | B52: 0 | C52: — | D52: — | E52: — | F52: — | G52: — | H52: — | I52: — | J52: Chưa làm
A53: Q49 | B53: 0 | C53: — | D53: — | E53: — | F53: — | G53: — | H53: — | I53: — | J53: Chưa làm
A54: Q50 | B54: 0 | C54: — | D54: — | E54: — | F54: — | G54: — | H54: — | I54: — | J54: Chưa làm

Sheet So sanh 3 phien
A1: Cùng trạng thái trước phiên 10 (ngày 17), ba loại phiên chọn 7 câu ôn khác nhau (+3 câu mới như nhau)
A3: Điểm yếu (7 câu Yếu) | I3: Củng cố (7 câu Sắp quên) | Q3: Cân bằng (4 Yếu + 3 Sắp quên)
A4: Mã câu | B4: Nhóm | C4: Lịch sử | D4: Độ yếu | E4: S | F4: t | G4: R | I4: Mã câu | J4: Nhóm | K4: Lịch sử | L4: Độ yếu | M4: S | N4: t | O4: R | Q4: Mã câu | R4: Nhóm | S4: Lịch sử | T4: Độ yếu | U4: S | V4: t | W4: R
A5: Q34 | B5: Yếu | C5: SS | D5: 0.75 | E5: 1 | F5: 4 | G5: 0.6561 | I5: Q16 | J5: Sắp quên | K5: ĐS | L5: 0.5 | M5: 1 | N5: 7 | O5: 0.4782969 | Q5: Q34 | R5: Yếu | S5: SS | T5: 0.75 | U5: 1 | V5: 4 | W5: 0.6561
A6: Q09 | B6: Yếu | C6: ĐSSS | D6: 0.66666667 | E6: 1 | F6: 4 | G6: 0.6561 | I6: Q20 | J6: Sắp quên | K6: Đ | L6: 0.33333333 | M6: 3 | N6: 14 | O6: 0.61159657 | Q6: Q09 | R6: Yếu | S6: ĐSSS | T6: 0.66666667 | U6: 1 | V6: 4 | W6: 0.6561
A7: Q38 | B7: Yếu | C7: S | D7: 0.66666667 | E7: 1 | F7: 4 | G7: 0.6561 | I7: Q22 | J7: Sắp quên | K7: Đ | L7: 0.33333333 | M7: 3 | N7: 13 | O7: 0.63345759 | Q7: Q38 | R7: Yếu | S7: S | T7: 0.66666667 | U7: 1 | V7: 4 | W7: 0.6561
A8: Q39 | B8: Yếu | C8: S | D8: 0.66666667 | E8: 1 | F8: 4 | G8: 0.6561 | I8: Q34 | J8: Sắp quên | K8: SS | L8: 0.75 | M8: 1 | N8: 4 | O8: 0.6561 | Q8: Q39 | R8: Yếu | S8: S | T8: 0.66666667 | U8: 1 | V8: 4 | W8: 0.6561
A9: Q12 | B9: Yếu | C9: ĐSS | D9: 0.6 | E9: 1 | F9: 4 | G9: 0.6561 | I9: Q09 | J9: Sắp quên | K9: ĐSSS | L9: 0.66666667 | M9: 1 | N9: 4 | O9: 0.6561 | Q9: Q16 | R9: Sắp quên | S9: ĐS | T9: 0.5 | U9: 1 | V9: 7 | W9: 0.4782969
A10: Q16 | B10: Yếu | C10: ĐS | D10: 0.5 | E10: 1 | F10: 7 | G10: 0.4782969 | I10: Q38 | J10: Sắp quên | K10: S | L10: 0.66666667 | M10: 1 | N10: 4 | O10: 0.6561 | Q10: Q20 | R10: Sắp quên | S10: Đ | T10: 0.33333333 | U10: 3 | V10: 14 | W10: 0.61159657
A11: Q10 | B11: Yếu | C11: SĐĐS | D11: 0.5 | E11: 1 | F11: 4 | G11: 0.6561 | I11: Q39 | J11: Sắp quên | K11: S | L11: 0.66666667 | M11: 1 | N11: 4 | O11: 0.6561 | Q11: Q22 | R11: Sắp quên | S11: Đ | T11: 0.33333333 | U11: 3 | V11: 13 | W11: 0.63345759
A14: Nhóm Yếu có 15 câu, nhóm Sắp quên có 37 câu, còn 11 câu chưa làm. Hai nhóm trùng nhau 15 câu.
A15: Cả ba phiên đều lấy thêm 3 câu mới: Q40, Q41, Q42.
